<?xml version="1.0" encoding="UTF-8"?>
<!-- Generated by org.testng.reporters.JUnitXMLReporter -->
<testsuite ignored="4" hostname="Yct201909022342" failures="1" tests="3" name="Default test" time="72.325" errors="0" timestamp="2020-07-07T22:03:26 CST">
  <testcase classname="com.lemon.testcase.LoginTest" name="loginSuccess" time="3.507">
    <skipped/>
  </testcase> <!-- loginSuccess -->
  <testcase classname="com.lemon.testcase.LoginTest" name="loginSuccess" time="3.082">
    <skipped/>
  </testcase> <!-- loginSuccess -->
  <testcase classname="com.lemon.testcase.LoginTest" name="loginSuccess" time="2.815">
    <failure type="java.lang.AssertionError" message="expected [前程贷官网 - 业内领先的社群互联网金融平台] but found [前程贷官网 - 欢迎登录]">
      <![CDATA[java.lang.AssertionError: expected [前程贷官网 - 业内领先的社群互联网金融平台] but found [前程贷官网 - 欢迎登录]
at org.testng.Assert.fail(Assert.java:97)
at org.testng.Assert.assertEqualsImpl(Assert.java:136)
at org.testng.Assert.assertEquals(Assert.java:118)
at org.testng.Assert.assertEquals(Assert.java:575)
at org.testng.Assert.assertEquals(Assert.java:585)
at com.lemon.testcase.LoginTest.loginSuccess(LoginTest.java:42)
at java.base/jdk.internal.reflect.NativeMethodAccessorImpl.invoke0(Native Method)
at java.base/jdk.internal.reflect.NativeMethodAccessorImpl.invoke(NativeMethodAccessorImpl.java:62)
at java.base/jdk.internal.reflect.DelegatingMethodAccessorImpl.invoke(DelegatingMethodAccessorImpl.java:43)
at java.base/java.lang.reflect.Method.invoke(Method.java:567)
at org.testng.internal.MethodInvocationHelper.invokeMethod(MethodInvocationHelper.java:133)
at org.testng.internal.TestInvoker.invokeMethod(TestInvoker.java:584)
at org.testng.internal.TestInvoker.retryFailed(TestInvoker.java:204)
at org.testng.internal.MethodRunner.runInSequence(MethodRunner.java:58)
at org.testng.internal.TestInvoker$MethodInvocationAgent.invoke(TestInvoker.java:804)
at org.testng.internal.TestInvoker.invokeTestMethods(TestInvoker.java:145)
at org.testng.internal.TestMethodWorker.invokeTestMethods(TestMethodWorker.java:146)
at org.testng.internal.TestMethodWorker.run(TestMethodWorker.java:128)
at java.base/java.util.ArrayList.forEach(ArrayList.java:1540)
at org.testng.TestRunner.privateRun(TestRunner.java:770)
at org.testng.TestRunner.run(TestRunner.java:591)
at org.testng.SuiteRunner.runTest(SuiteRunner.java:402)
at org.testng.SuiteRunner.runSequentially(SuiteRunner.java:396)
at org.testng.SuiteRunner.privateRun(SuiteRunner.java:355)
at org.testng.SuiteRunner.run(SuiteRunner.java:304)
at org.testng.SuiteRunnerWorker.runSuite(SuiteRunnerWorker.java:53)
at org.testng.SuiteRunnerWorker.run(SuiteRunnerWorker.java:96)
at org.testng.TestNG.runSuitesSequentially(TestNG.java:1180)
at org.testng.TestNG.runSuitesLocally(TestNG.java:1102)
at org.testng.TestNG.runSuites(TestNG.java:1032)
at org.testng.TestNG.run(TestNG.java:1000)
at org.testng.remote.AbstractRemoteTestNG.run(AbstractRemoteTestNG.java:115)
at org.testng.remote.RemoteTestNG.initAndRun(RemoteTestNG.java:251)
at org.testng.remote.RemoteTestNG.main(RemoteTestNG.java:77)
]]>
    </failure>
  </testcase> <!-- loginSuccess -->
  <testcase classname="com.lemon.testcase.LoginTest" name="loginFail01" time="0.0">
    <ignored/>
  </testcase> <!-- loginFail01 -->
  <testcase classname="com.lemon.testcase.LoginTest" name="rememberPhone" time="0.0">
    <ignored/>
  </testcase> <!-- rememberPhone -->
  <testcase classname="com.lemon.testcase.LoginTest" name="loginFail02" time="0.0">
    <ignored/>
  </testcase> <!-- loginFail02 -->
  <testcase classname="com.lemon.testcase.LoginTest" name="forgetPhone" time="0.0">
    <ignored/>
  </testcase> <!-- forgetPhone -->
</testsuite> <!-- Default test -->
